import pg, traceback, sys

class CatsOkError( Exception):
    value = None

    def __init__( self, value):
        self.value = value
        print >> sys.stderr, sys.exc_info()[0]
        print >> sys.stderr, '-'*60
        traceback.print_exc(file=sys.stderr)
        print >> sys.stderr, '-'*60

    def __str__( self):
        return repr( self.value)


class _Q:
    
    db = None   # our database connection

    def open( self):
        self.db = pg.connect( dbname="ls", host="postgres.ls-cat.net", user="lsuser" )

    def close( self):
        self.db.close()

    def __init__( self):
        self.open()

    def reset( self):
        self.db.reset()

    def query( self, qs):
        if qs == '':
            return rtn
        if self.db.status == 0:
            self.reset()
        try:
            # ping the server
            qr = self.db.query(qs)
        except:
            if self.db.status == 1:
                print >> sys.stderr, sys.exc_info()[0]
                print >> sys.stderr, '-'*60
                traceback.print_exc(file=sys.stderr)
                print >> sys.stderr, '-'*60
                return None
            # reset the connection, should
            # put in logic here to deal with transactions
            # as transactions are rolled back
            #
            self.db.reset()
            if self.db.status != 1:
                # Bad status even after a reset, bail
                raise CatsOkError( 'Database Connection Lost')

            qr = self.db.query( qs)

        return qr

    def dictresult( self, qr):
        return qr.dictresult()

    def e( self, s):
        return pg.escape_string( s)

    def fileno( self):
        return self.db.fileno()

    def getnotify( self):
        return self.db.getnotify()



class distTest:
    dists = [200,250,300,350,400,450,500,550,600]
    _q = None

    def __init__( self, stn):
        self._q = _Q()

    def run( self):
        
